Workbook

Sheet Naiwny klasyfikator Bayesa
B1: Atrybut
B2: x1 | C2: x2 | D2: x3 | E2: d
A3: Nr obserwacji | B3: Siła wiatru | C3: Zachmurzenie | D3: Odczuwalna temperatura | E3: Zagrano mecz
A4: 1 | B4: silny | C4: pochmurnie | D4: zimno | E4: nie
A5: 2 | B5: silny | C5: pochmurnie | D5: ciepło | E5: nie
A6: 3 | B6: brak | C6: słonecznie | D6: ciepło | E6: tak
A7: 4 | B7: brak | C7: słonecznie | D7: gorąco | E7: nie
A8: 5 | B8: słaby | C8: pochmurnie | D8: gorąco | E8: tak
A9: 6 | B9: słaby | C9: słonecznie | D9: ciepło | E9: tak
A10: 7 | B10: brak | C10: pochmurnie | D10: zimno | E10: nie
A11: 8 | B11: silny | C11: słonecznie | D11: zimno | E11: tak
A12: 9 | B12: brak | C12: pochmurnie | D12: gorąco | E12: tak
A13: 10 | B13: silny | C13: pochmurnie | D13: ciepło | E13: tak
A14: 11 | B14: silny | C14: słonecznie | D14: ciepło | E14: ?
A17: Naiwny klasyfikator Bayesa
A19: Przypadek (obiekt), który chcemy sklasyfikować oznaczymy jako X jest scharakteryzowany jako X=[x1, x2, x3]=[silny, słonecznie, ciepło].
A20: Przypadek X mamy sklasyfikować do jednej z klas: C1 = {d=tak}, C2 = {d=nie}
A22: A więc szukamy takiej decyzji d^* ∈ {tak, nie}, że
A27: (Czyli takiej, dla której iloczyn prawdopodbieństwa klasy oraz prawdopoboieństw wszystkich cech jest największy.)
A29: Pamiętając, że
B36: x1 | C36: d
A37: Nr obserwacji | B37: Siła wiatru | C37: Zagrano mecz
A38: 1 | B38: silny | C38: nie
A39: 2 | B39: silny | C39: nie
A40: 3 | B40: brak | C40: tak
A41: 4 | B41: brak | C41: nie
A42: 5 | B42: słaby | C42: tak
A43: 6 | B43: słaby | C43: tak
A44: 7 | B44: brak | C44: nie
A45: 8 | B45: silny | C45: tak
A46: 9 | B46: brak | C46: tak
A47: 10 | B47: silny | C47: tak
A48: 11 | B48: silny | C48: ?
B52: x2 | C52: d
A53: Nr obserwacji | B53: Zachmurzenie | C53: Zagrano mecz
A54: 1 | B54: pochmurnie | C54: nie
A55: 2 | B55: pochmurnie | C55: nie
A56: 3 | B56: słonecznie | C56: tak
A57: 4 | B57: słonecznie | C57: nie
A58: 5 | B58: pochmurnie | C58: tak
...

Sheet Metoda najbliższego sąsiedztwa
B1: Atrybut
B2: x1 | C2: x2 | D2: x3 | E2: d | F2: d_e^2 | G2: d_e | H2: d_m
A3: Nr obserwacji | B3: Siła wiatru | C3: Zachmurzenie | D3: Odczuwalna temperatura | E3: Zagrano mecz | F3: Kwadrat odległości euklidesowej | G3: Odległość euklidesowa | H3: Odległość miejska
A4: 1 | B4: =CHOOSE(MATCH('Naiwny klasyfikator Bayesa'!B4,{"brak";"słaby";"silny"},0),0,1,2) -> 2 | C4: =CHOOSE(MATCH('Naiwny klasyfikator Bayesa'!C4,{"pochmurnie";"słonecznie"},0),0,1) -> 0 | D4: =CHOOSE(MATCH('Naiwny klasyfikator Bayesa'!D4,{"zimno";"ciepło";"gorąco"},0),0,1,2) -> 0 | E4: =CHOOSE(MATCH('Naiwny klasyfikator Bayesa'!E4,{"nie";"tak"},0),0,1) -> 0 | F4: {=SUMPRODUCT((B4:D4-$B$14:$D$14)^2)} -> 2 | G4: =SQRT(F4) -> 1.4142136 | H4: {=SUMPRODUCT(ABS(B4:D4-$B$14:$D$14))} -> 2
A5: 2 | B5: =CHOOSE(MATCH('Naiwny klasyfikator Bayesa'!B5,{"brak";"słaby";"silny"},0),0,1,2) -> 2 | C5: =CHOOSE(MATCH('Naiwny klasyfikator Bayesa'!C5,{"pochmurnie";"słonecznie"},0),0,1) -> 0 | D5: =CHOOSE(MATCH('Naiwny klasyfikator Bayesa'!D5,{"zimno";"ciepło";"gorąco"},0),0,1,2) -> 1 | E5: =CHOOSE(MATCH('Naiwny klasyfikator Bayesa'!E5,{"nie";"tak"},0),0,1) -> 0 | F5: {=SUMPRODUCT((B5:D5-$B$14:$D$14)^2)} -> 1 | G5: =SQRT(F5) -> 1 | H5: {=SUMPRODUCT(ABS(B5:D5-$B$14:$D$14))} -> 1
A6: 3 | B6: =CHOOSE(MATCH('Naiwny klasyfikator Bayesa'!B6,{"brak";"słaby";"silny"},0),0,1,2) -> 0 | C6: =CHOOSE(MATCH('Naiwny klasyfikator Bayesa'!C6,{"pochmurnie";"słonecznie"},0),0,1) -> 1 | D6: =CHOOSE(MATCH('Naiwny klasyfikator Bayesa'!D6,{"zimno";"ciepło";"gorąco"},0),0,1,2) -> 1 | E6: =CHOOSE(MATCH('Naiwny klasyfikator Bayesa'!E6,{"nie";"tak"},0),0,1) -> 1 | F6: {=SUMPRODUCT((B6:D6-$B$14:$D$14)^2)} -> 4 | G6: =SQRT(F6) -> 2 | H6: {=SUMPRODUCT(ABS(B6:D6-$B$14:$D$14))} -> 2
A7: 4 | B7: =CHOOSE(MATCH('Naiwny klasyfikator Bayesa'!B7,{"brak";"słaby";"silny"},0),0,1,2) -> 0 | C7: =CHOOSE(MATCH('Naiwny klasyfikator Bayesa'!C7,{"pochmurnie";"słonecznie"},0),0,1) -> 1 | D7: =CHOOSE(MATCH('Naiwny klasyfikator Bayesa'!D7,{"zimno";"ciepło";"gorąco"},0),0,1,2) -> 2 | E7: =CHOOSE(MATCH('Naiwny klasyfikator Bayesa'!E7,{"nie";"tak"},0),0,1) -> 0 | F7: {=SUMPRODUCT((B7:D7-$B$14:$D$14)^2)} -> 5 | G7: =SQRT(F7) -> 2.236068 | H7: {=SUMPRODUCT(ABS(B7:D7-$B$14:$D$14))} -> 3
A8: 5 | B8: =CHOOSE(MATCH('Naiwny klasyfikator Bayesa'!B8,{"brak";"słaby";"silny"},0),0,1,2) -> 1 | C8: =CHOOSE(MATCH('Naiwny klasyfikator Bayesa'!C8,{"pochmurnie";"słonecznie"},0),0,1) -> 0 | D8: =CHOOSE(MATCH('Naiwny klasyfikator Bayesa'!D8,{"zimno";"ciepło";"gorąco"},0),0,1,2) -> 2 | E8: =CHOOSE(MATCH('Naiwny klasyfikator Bayesa'!E8,{"nie";"tak"},0),0,1) -> 1 | F8: {=SUMPRODUCT((B8:D8-$B$14:$D$14)^2)} -> 3 | G8: =SQRT(F8) -> 1.7320508 | H8: {=SUMPRODUCT(ABS(B8:D8-$B$14:$D$14))} -> 3
A9: 6 | B9: =CHOOSE(MATCH('Naiwny klasyfikator Bayesa'!B9,{"brak";"słaby";"silny"},0),0,1,2) -> 1 | C9: =CHOOSE(MATCH('Naiwny klasyfikator Bayesa'!C9,{"pochmurnie";"słonecznie"},0),0,1) -> 1 | D9: =CHOOSE(MATCH('Naiwny klasyfikator Bayesa'!D9,{"zimno";"ciepło";"gorąco"},0),0,1,2) -> 1 | E9: =CHOOSE(MATCH('Naiwny klasyfikator Bayesa'!E9,{"nie";"tak"},0),0,1) -> 1 | F9: {=SUMPRODUCT((B9:D9-$B$14:$D$14)^2)} -> 1 | G9: =SQRT(F9) -> 1 | H9: {=SUMPRODUCT(ABS(B9:D9-$B$14:$D$14))} -> 1
A10: 7 | B10: =CHOOSE(MATCH('Naiwny klasyfikator Bayesa'!B10,{"brak";"słaby";"silny"},0),0,1,2) -> 0 | C10: =CHOOSE(MATCH('Naiwny klasyfikator Bayesa'!C10,{"pochmurnie";"słonecznie"},0),0,1) -> 0 | D10: =CHOOSE(MATCH('Naiwny klasyfikator Bayesa'!D10,{"zimno";"ciepło";"gorąco"},0),0,1,2) -> 0 | E10: =CHOOSE(MATCH('Naiwny klasyfikator Bayesa'!E10,{"nie";"tak"},0),0,1) -> 0 | F10: {=SUMPRODUCT((B10:D10-$B$14:$D$14)^2)} -> 6 | G10: =SQRT(F10) -> 2.4494897 | H10: {=SUMPRODUCT(ABS(B10:D10-$B$14:$D$14))} -> 4
A11: 8 | B11: =CHOOSE(MATCH('Naiwny klasyfikator Bayesa'!B11,{"brak";"słaby";"silny"},0),0,1,2) -> 2 | C11: =CHOOSE(MATCH('Naiwny klasyfikator Bayesa'!C11,{"pochmurnie";"słonecznie"},0),0,1) -> 1 | D11: =CHOOSE(MATCH('Naiwny klasyfikator Bayesa'!D11,{"zimno";"ciepło";"gorąco"},0),0,1,2) -> 0 | E11: =CHOOSE(MATCH('Naiwny klasyfikator Bayesa'!E11,{"nie";"tak"},0),0,1) -> 1 | F11: {=SUMPRODUCT((B11:D11-$B$14:$D$14)^2)} -> 1 | G11: =SQRT(F11) -> 1 | H11: {=SUMPRODUCT(ABS(B11:D11-$B$14:$D$14))} -> 1
A12: 9 | B12: =CHOOSE(MATCH('Naiwny klasyfikator Bayesa'!B12,{"brak";"słaby";"silny"},0),0,1,2) -> 0 | C12: =CHOOSE(MATCH('Naiwny klasyfikator Bayesa'!C12,{"pochmurnie";"słonecznie"},0),0,1) -> 0 | D12: =CHOOSE(MATCH('Naiwny klasyfikator Bayesa'!D12,{"zimno";"ciepło";"gorąco"},0),0,1,2) -> 2 | E12: =CHOOSE(MATCH('Naiwny klasyfikator Bayesa'!E12,{"nie";"tak"},0),0,1) -> 1 | F12: {=SUMPRODUCT((B12:D12-$B$14:$D$14)^2)} -> 6 | G12: =SQRT(F12) -> 2.4494897 | H12: {=SUMPRODUCT(ABS(B12:D12-$B$14:$D$14))} -> 4
A13: 10 | B13: =CHOOSE(MATCH('Naiwny klasyfikator Bayesa'!B13,{"brak";"słaby";"silny"},0),0,1,2) -> 2 | C13: =CHOOSE(MATCH('Naiwny klasyfikator Bayesa'!C13,{"pochmurnie";"słonecznie"},0),0,1) -> 0 | D13: =CHOOSE(MATCH('Naiwny klasyfikator Bayesa'!D13,{"zimno";"ciepło";"gorąco"},0),0,1,2) -> 1 | E13: =CHOOSE(MATCH('Naiwny klasyfikator Bayesa'!E13,{"nie";"tak"},0),0,1) -> 1 | F13: {=SUMPRODUCT((B13:D13-$B$14:$D$14)^2)} -> 1 | G13: =SQRT(F13) -> 1 | H13: {=SUMPRODUCT(ABS(B13:D13-$B$14:$D$14))} -> 1
A14: 11 | B14: =CHOOSE(MATCH('Naiwny klasyfikator Bayesa'!B14,{"brak";"słaby";"silny"},0),0,1,2) -> 2 | C14: =CHOOSE(MATCH('Naiwny klasyfikator Bayesa'!C14,{"pochmurnie";"słonecznie"},0),0,1) -> 1 | D14: =CHOOSE(MATCH('Naiwny klasyfikator Bayesa'!D14,{"zimno";"ciepło";"gorąco"},0),0,1,2) -> 1 | E14: ? | F14: {=SUMPRODUCT((B14:D14-$B$14:$D$14)^2)} -> 0 | G14: =SQRT(F14) -> 0 | H14: {=SUMPRODUCT(ABS(B14:D14-$B$14:$D$14))} -> 0
A17: Atrybuty zostały zakodowane liczbowo z zachowaniem ich naturalnego porządku (np. siła wiatru: brak < słaby < silny), co umożliwiło obliczanie odległości w metodzie najbliższego sąsiedztwa.
A22: Metoda najbliższego sąsiedztwa - odległość euklidesowa, głosowanie proste
A24: Predykcja dla przypadku (obiektu) o numerze 11:
A26: Dla k=1
A27: Najmniejsza odległość wynosi 1, istnieją 4 przypadki z taką odległością, więc mimo że k=1 - jeden najbliższy sąsiad, musimy uwzględnić je wszystkie:
B30: d | C30: d_e | F30: Klasa "0" | G30: Klasa "1"
A31: Nr obserwacji | B31: Zagrano mecz | C31: Odległość euklidesowa | E31: Liczba wystąpień | F31: 1 | G31: 3
A32: 2 | B32: =$E$5 -> 0 | C32: =$G$5 -> 1
A33: 6 | B33: =$E$9 -> 1 | C33: =$G$9 -> 1
A34: 8 | B34: =$E$11 -> 1 | C34: =$G$11 -> 1
A35: 10 | B35: =$E$13 -> 1 | C35: =$G$13 -> 1
A37: Decyzja przynalezności obiektu 11: klasa "1", ponieważ wystąpiła ona większa liczbę razy.
A39: Dla k=2, k=3, k=4 obiekt 11 również sklasyfikujemy do klasy "1", bo dalej mamy do czynienia z remisem odległości i liczba najbliższych sąsiadów pozostanie taka sama.
A42: Dla k=5
A43: Piąty najbliższy sąsiad to obiekt nr 1 o odległości 1,41, który przynależy do klasy "0". Podsumowanie wszystkich pięciu najbliższych obiektów znajduje się poniżej.
B46: d | C46: d_e
A47: Nr obserwacji | B47: Zagrano mecz | C47: Odległość euklidesowa | F47: Klasa "0" | G47: Klasa "1"
A48: 2 | B48: =$E$5 -> 0 | C48: =$G$5 -> 1 | E48: Liczba wystąpień | F48: 2 | G48: 3
A49: 6 | B49: =$E$9 -> 1 | C49: =$G$9 -> 1
A50: 8 | B50: =$E$11 -> 1 | C50: =$G$11 -> 1
A51: 10 | B51: =$E$13 -> 1 | C51: =$G$13 -> 1
A52: 1 | B52: =$E$4 -> 0 | C52: =$G$4 -> 1.4142136
A54: Decyzja przynalezności obiektu 11: klasa "1", ponieważ wystąpiła ona większa liczbę razy.
A57: Dla k=6
A58: Szósty najbliższy sąsiad to obiekt nr 5 o odległości 1,73, który przynależy do klasy "1". Podsumowanie wszystkich sześciu najbliższych obiektów znajduje się poniżej.
B61: d | C61: d_e
...
